<?xml version="1.0" encoding="utf-8"?>
<!-- This URDF was automatically created by SolidWorks to URDF Exporter! Originally created by Stephen Brawner (brawner@gmail.com) 
     Commit Version: 1.6.0-4-g7f85cfe  Build Version: 1.6.7995.38578
     For more information, please see http://wiki.ros.org/sw_urdf_exporter -->
<robot
  name="UR3 Assembly.SLDASM">
  <link
    name="base_link">
    <inertial>
      <origin
        xyz="2.10331451958708E-17 -2.85373966699829E-17 0.0318014583182494"
        rpy="0 0 0" />
      <mass
        value="0.349927574489805" />
      <inertia
        ixx="0.000850315175929104"
        ixy="-4.1445876930932E-19"
        ixz="1.6580410083251E-19"
        iyy="0.000850315175929105"
        iyz="-2.9682903266316E-19"
        izz="0.000961065577007259" />
    </inertial>
    <visual>
      <origin
        xyz="0 0 0"
        rpy="0 0 0" />
      <geometry>
        <mesh
          filename="package://UR3 Assembly.SLDASM/meshes/base_link.STL" />
      </geometry>
      <material
        name="">
        <color
          rgba="0.898039215686275 0.917647058823529 0.929411764705882 1" />
      </material>
    </visual>
    <collision>
      <origin
        xyz="0 0 0"
        rpy="0 0 0" />
      <geometry>
        <mesh
          filename="package://UR3 Assembly.SLDASM/meshes/base_link.STL" />
      </geometry>
    </collision>
  </link>
  <link
    name="shoulder_link">
    <inertial>
      <origin
        xyz="-5.85822743935513E-07 0.0152431791788375 0.00049236327818796"
        rpy="0 0 0" />
      <mass
        value="0.591922355681539" />
      <inertia
        ixx="0.00124366958821844"
        ixy="8.82302175776178E-09"
        ixz="-9.21599018492836E-09"
        iyy="0.00129022662441192"
        iyz="-0.000105188115684273"
        izz="0.00127028553989303" />
    </inertial>
    <visual>
      <origin
        xyz="0 0 0"
        rpy="0 0 0" />
      <geometry>
        <mesh
          filename="package://UR3 Assembly.SLDASM/meshes/shoulder_link.STL" />
      </geometry>
      <material
        name="">
        <color
          rgba="0.647058823529412 0.619607843137255 0.588235294117647 1" />
      </material>
    </visual>
    <collision>
      <origin
        xyz="0 0 0"
        rpy="0 0 0" />
      <geometry>
        <mesh
          filename="package://UR3 Assembly.SLDASM/meshes/shoulder_link.STL" />
      </geometry>
    </collision>
  </link>
  <joint
    name="joint1"
    type="fixed">
    <origin
      xyz="0 -0.010918 0.15225"
      rpy="0 0 0" />
    <parent
      link="base_link" />
    <child
      link="shoulder_link" />
    <axis
      xyz="0 0 0" />
    <limit
      lower="0"
      upper="0"
      effort="0"
      velocity="0" />
  </joint>
  <link
    name="upper_link">
    <inertial>
      <origin
        xyz="5.85822743909011E-07 0.00049236327818801 0.0152431791788375"
        rpy="0 0 0" />
      <mass
        value="0.591922355681539" />
      <inertia
        ixx="0.00124366958821844"
        ixy="9.21599018488105E-09"
        ixz="-8.82302175688512E-09"
        iyy="0.00127028553989302"
        iyz="-0.000105188115684272"
        izz="0.00129022662441192" />
    </inertial>
    <visual>
      <origin
        xyz="0 0 0"
        rpy="0 0 0" />
      <geometry>
        <mesh
          filename="package://UR3 Assembly.SLDASM/meshes/upper_link.STL" />
      </geometry>
      <material
        name="">
        <color
          rgba="0.647058823529412 0.619607843137255 0.588235294117647 1" />
      </material>
    </visual>
    <collision>
      <origin
        xyz="0 0 0"
        rpy="0 0 0" />
      <geometry>
        <mesh
          filename="package://UR3 Assembly.SLDASM/meshes/upper_link.STL" />
      </geometry>
    </collision>
  </link>
  <joint
    name="joint2"
    type="fixed">
    <origin
      xyz="0 0.11837 0.001635"
      rpy="0 0 0" />
    <parent
      link="shoulder_link" />
    <child
      link="upper_link" />
    <axis
      xyz="0 0 0" />
    <limit
      lower="0"
      upper="0"
      effort="0"
      velocity="0" />
  </joint>
  <link
    name="forearm_link">
    <inertial>
      <origin
        xyz="1.74841459405462E-07 0.00343800961310815 0.00339328641588776"
        rpy="0 0 0" />
      <mass
        value="0.127550762978422" />
      <inertia
        ixx="0.000153369640250036"
        ixy="4.8943130829217E-10"
        ixz="-1.52084842258724E-09"
        iyy="0.00016270011377508"
        iyz="2.29301050405186E-05"
        izz="0.000153398255945326" />
    </inertial>
    <visual>
      <origin
        xyz="0 0 0"
        rpy="0 0 0" />
      <geometry>
        <mesh
          filename="package://UR3 Assembly.SLDASM/meshes/forearm_link.STL" />
      </geometry>
      <material
        name="">
        <color
          rgba="0.898039215686275 0.917647058823529 0.929411764705882 1" />
      </material>
    </visual>
    <collision>
      <origin
        xyz="0 0 0"
        rpy="0 0 0" />
      <geometry>
        <mesh
          filename="package://UR3 Assembly.SLDASM/meshes/forearm_link.STL" />
      </geometry>
    </collision>
  </link>
  <joint
    name="joint3"
    type="fixed">
    <origin
      xyz="0 -0.076371 0.26173"
      rpy="0 0 0" />
    <parent
      link="upper_link" />
    <child
      link="forearm_link" />
    <axis
      xyz="0 0 0" />
    <limit
      lower="0"
      upper="0"
      effort="0"
      velocity="0" />
  </joint>
  <link
    name="wrist1">
    <inertial>
      <origin
        xyz="1.40036711622926E-06 0.00131641802949848 -0.0121255503643865"
        rpy="0 0 0" />
      <mass
        value="0.313166527249699" />
      <inertia
        ixx="0.000344082152180982"
        ixy="-1.99231995681272E-10"
        ixz="1.98765653225625E-09"
        iyy="0.000346650224316672"
        iyz="-2.77487608069233E-05"
        izz="0.000350362375942286" />
    </inertial>
    <visual>
      <origin
        xyz="0 0 0"
        rpy="0 0 0" />
      <geometry>
        <mesh
          filename="package://UR3 Assembly.SLDASM/meshes/wrist1.STL" />
      </geometry>
      <material
        name="">
        <color
          rgba="0.647058823529412 0.619607843137255 0.588235294117647 1" />
      </material>
    </visual>
    <collision>
      <origin
        xyz="0 0 0"
        rpy="0 0 0" />
      <geometry>
        <mesh
          filename="package://UR3 Assembly.SLDASM/meshes/wrist1.STL" />
      </geometry>
    </collision>
  </link>
  <joint
    name="joint4"
    type="fixed">
    <origin
      xyz="0 -0.00088763 0.21452"
      rpy="0 0 0" />
    <parent
      link="forearm_link" />
    <child
      link="wrist1" />
    <axis
      xyz="0 0 0" />
    <limit
      lower="0"
      upper="0"
      effort="0"
      velocity="0" />
  </joint>
  <link
    name="wrist2">
    <inertial>
      <origin
        xyz="-9.85205795892191E-07 -0.00833419482293968 0.0117119322272001"
        rpy="0 0 0" />
      <mass
        value="0.73042030766759" />
      <inertia
        ixx="0.000351951807882449"
        ixy="-2.61657085712266E-21"
        ixz="7.62300143294477E-20"
        iyy="0.000351951807882449"
        iyz="-4.60862614855964E-20"
        izz="0.000318645859219986" />
    </inertial>
    <visual>
      <origin
        xyz="0 0 0"
        rpy="0 0 0" />
      <geometry>
        <mesh
          filename="package://UR3 Assembly.SLDASM/meshes/wrist2.STL" />
      </geometry>
      <material
        name="">
        <color
          rgba="0.686274509803922 0.658823529411765 0.63921568627451 1" />
      </material>
    </visual>
    <collision>
      <origin
        xyz="0 0 0"
        rpy="0 0 0" />
      <geometry>
        <mesh
          filename="package://UR3 Assembly.SLDASM/meshes/wrist2.STL" />
      </geometry>
    </collision>
  </link>
  <joint
    name="joint5"
    type="continuous">
    <origin
      xyz="0 0.088146 -0.0051461"
      rpy="0 0 0" />
    <parent
      link="wrist1" />
    <child
      link="wrist2" />
    <axis
      xyz="0 0 1" />
    <limit
      lower="0"
      upper="0"
      effort="0"
      velocity="0" />
  </joint>
  <link
    name="wrist3">
    <inertial>
      <origin
        xyz="-2.58841036661401E-07 -0.000780273847138302 -0.0103210763383818"
        rpy="0 0 0" />
      <mass
        value="0.351918582087952" />
      <inertia
        ixx="0.000433081633416597"
        ixy="-3.10492613803927E-08"
        ixz="-1.87259614944318E-08"
        iyy="0.000385075387508618"
        iyz="-3.38880522683126E-05"
        izz="0.000438880302194999" />
    </inertial>
    <visual>
      <origin
        xyz="0 0 0"
        rpy="0 0 0" />
      <geometry>
        <mesh
          filename="package://UR3 Assembly.SLDASM/meshes/wrist3.STL" />
      </geometry>
      <material
        name="">
        <color
          rgba="0.647058823529412 0.619607843137255 0.588235294117647 1" />
      </material>
    </visual>
    <collision>
      <origin
        xyz="0 0 0"
        rpy="0 0 0" />
      <geometry>
        <mesh
          filename="package://UR3 Assembly.SLDASM/meshes/wrist3.STL" />
      </geometry>
    </collision>
  </link>
  <joint
    name="joint6"
    type="fixed">
    <origin
      xyz="0 0.0024047 0.086763"
      rpy="0 0 0" />
    <parent
      link="wrist2" />
    <child
      link="wrist3" />
    <axis
      xyz="0 0 0" />
    <limit
      lower="0"
      upper="0"
      effort="0"
      velocity="0" />
  </joint>
</robot>